Workbook

Sheet Th. Lulus 2016
G1: A | P1: B | U1: C | W1: D | Y1: E | AA1: F | AD1: G | AF1: H | AJ1: I.a | AO1: I.b | AS1: J | AW1: K1 | BC1: L1
B2: th lulus | C2: Program Pendidikan | D2: Prodi | E2: Nim | F2: Nama Alumni | G2: A1 | H2: A2 | I2: A3 | J2: A4 | K2: A5 | L2: A6 | M2: A7 | N2: A8 | O2: A9 Bulan | P2: B1 | Q2: B2 | R2: B3 | S2: B4 | T2: B5 | U2: C1 | V2: C2 | W2: D1 | X2: D2 | Y2: E1 | Z2: E2 | AA2: F1 | AB2: F2 | AC2: F3 | AD2: G1 | AE2: G2 | AF2: H1 | AG2: H2 | AH2: H3 | AI2: H4 | AJ2: I. a1 | AK2: I. a2 | AL2: I. a3 | AM2: I. a4 | AN2: I. a5 | AO2: I. b1 | AP2: I. b2 | AQ2: I. b3 | AR2: I. b4 | AS2: J1 | AT2: J2 | AU2: J3 | AV2: J4 | AW2: K1 | AX2: K2 | AY2: K3 | AZ2: K4 | BA2: K5 | BB2: K6 | BC2: L1 | BD2: L2 | BE2: L3
B3: 2016 | C3: Diploma Tiga | D3: D3 Administrasi Perkantoran | E3: 13390150004 | F3: Adhaji Vidananto | G3: Janu Bagus Girianto | H3: 081335601085 | I3: Janu.Bagus@aplog.com | J3: PT. Angkasa Pura Logiskik | K3: Area Terminal Kargo Bandara Udara Juanda | L3: 031-8683342 | M3: Logistik | N3: 1 | O3: 1 | P3: SB | Q3: B | R3: B | S3: B | T3: SB | U3: K | V3: SB | W3: B | X3: B | Y3: B | Z3: B | AA3: SB | AB3: SB | AC3: SB | AD3: SB | AE3: B | AF3: B | AG3: B | AH3: SB | AI3: SB | AJ3: B | AK3: K | AL3: SB | AM3: B | AN3: SB | AO3: B | AP3: SB | AQ3: B | AR3: B | AS3: Perlu | AU3: Ya | AW3: Tidak | AX3: Tidak | AY3: Tidak | AZ3: Ya | BA3: Tidak | BC3: SB
B4: 2016 | C4: Diploma Tiga | D4: D3 Administrasi Perkantoran | E4: 12390150001 | F4: Niken Revalasha | G4: Fauzan | H4: - | I4: - | J4: Angkasa Pura Support Cabang Surabaya | K4: - | L4: - | M4: Pelayanan customer | N4: 5 | O4: 60 | P4: SB | Q4: SB | R4: SB | S4: SB | T4: SB | U4: B | V4: SB | W4: SB | X4: SB | Y4: B | Z4: SB | AA4: SB | AB4: SB | AC4: SB | AD4: SB | AE4: SB | AF4: SB | AG4: SB | AH4: B | AI4: SB | AJ4: SB | AK4: SB | AL4: SB | AM4: SB | AN4: SB | AO4: SB | AP4: B | AQ4: SB | AR4: SB | AS4: Tidak Perlu | AT4: - | AU4: Tidak | AV4: - | AW4: Ya | AX4: Ya | AY4: Tidak | AZ4: Tidak | BA4: Ya | BB4: - | BC4: SB | BD4: Penggunaan TI, Pengembangan Diri | BE4: -
B5: 2016 | C5: Diploma Tiga | D5: D3 Sistem Informasi | E5: 12390100006 | F5: Chumsoni Dwi Abdul Ghofur | G5: Rudy Prastowo | H5: 08123008965 | I5: rudyprastowo40@gmail.com | J5: PT Golden Ocean Line | K5: Jl. Indrapura 29-33 Surabaya | L5: 313579374 | M5: Jasa Angkutan Laut | N5: 1 | O5: 12 | P5: B | Q5: B | R5: B | S5: B | T5: SB | U5: B | V5: B | W5: K | X5: K | Y5: B | Z5: B | AA5: B | AB5: B | AC5: B | AD5: B | AE5: B | AF5: B | AG5: B | AH5: B | AI5: B | AJ5: B | AK5: B | AL5: B | AM5: B | AN5: B | AO5: B | AP5: B | AQ5: B | AR5: B | AS5: Perlu | AT5: Intensipkan Bahasa Inggris | AU5: Ya | AV5: Sytem dan Program Diperlukan | AW5: Tidak | AX5: Tidak | AY5: Ya | AZ5: Tidak | BA5: Tidak | BC5: B | BD5: Bahasa Inggris, Pengembangan diri | BE5: Mahir mengoperasikan sistem komputer dan menguasai bahasa inggris untuk komunikasi dengan luar negeri
B6: 2016 | C6: Diploma Tiga | D6: D3 Sistem Informasi | E6: 13390100011 | F6: Nur Mawartiningsih | G6: - | H6: - | I6: - | J6: PT. Dua Kelinci | K6: Jl. HR Muhammad No.24, (New Land Office) | L6: - | M6: Perdagangan / Bisnis | N6: 1 | O6: 12 | P6: B | Q6: B | R6: B | S6: B | T6: SB | U6: B | V6: B | W6: K | X6: K | Y6: SB | Z6: SB | AA6: SB | AB6: SB | AC6: SB | AD6: SB | AE6: SB | AF6: B | AG6: B | AH6: B | AI6: B | AJ6: B | AK6: B | AL6: B | AM6: B | AN6: B | AO6: SB | AP6: SB | AQ6: SB | AR6: SB | AS6: Perlu | AT6: - | AU6: Ya | AV6: - | AW6: Tidak | AX6: Tidak | AY6: Tidak | AZ6: Tidak | BA6: Tidak | BB6: - | BC6: B | BD6: - | BE6: -
B7: 2016 | C7: Diploma Tiga | D7: D3 Sistem Informasi | E7: 13390100013 | F7: Dian Arif Rachman | G7: Cristoforus H Alcadi | I7: krist.ha@staff.ubaya.ac.id | J7: Universitas Surabaya | K7: Raya Kalirungkut | L7: 2981040 | M7: Pendidikan | N7: 4 | O7: 60 | P7: SB | Q7: SB | R7: B | S7: B | T7: B | U7: SB | V7: SB | W7: B | X7: B | Y7: SB | Z7: SB | AA7: SB | AB7: SB | AC7: SB | AD7: SB | AE7: SB | AF7: SB | AG7: SB | AH7: SB | AI7: SB | AJ7: SB | AK7: SB | AL7: SB | AM7: SB | AN7: SB | AO7: SB | AP7: SB | AQ7: SB | AR7: SB | AS7: Perlu | AT7: Materi tentang komunikasi, kepemimpinan dan softskill lainnya | AU7: Ya | AV7: Lulusan yang siap terjun dalam pengembangan teknologi informasi terapan | AW7: Ya | AX7: Tidak | AY7: Ya | AZ7: Tidak | BA7: Tidak | BB7: Saat ini belum ada | BC7: B | BD7: Bahasa Inggris, Komunikasi, pengembangan diri, kepemimpinan, memeahami apa yang haarus dilakuakan dalam pekerjaan | BE7: Jujur, integritas, skill teknis IT yang memadai (tinggi), bekerjasama dengan tim, pemahaman proses bisnis organisasi / perusahaan yang tinggi, keluwesan dalam penyesuaian diridengan dinamika organisasi
B8: 2016 | C8: Diploma Tiga | D8: D3 Sistem Informasi | E8: 13390100021 | F8: Fajar Riska Daniakso | G8: Tri Septa | H8: 0817337274 | J8: Dinas Perpustakaan dan Kearsipan | K8: Gedung Siola Lt. 4 | M8: Instansi pemerintahan | N8: 1 | O8: 12 | P8: B | Q8: SB | R8: B | S8: SB | T8: SB | U8: B | V8: B | W8: B | X8: B | Y8: SB | Z8: B | AA8: SB | AB8: B | AC8: B | AD8: B | AE8: B | AF8: SB | AG8: B | AH8: SB | AI8: B | AJ8: B | AK8: SB | AL8: B | AM8: B | AN8: B | AO8: B | AP8: B | AQ8: B | AR8: B | AS8: Perlu | AU8: Ya | AW8: Tidak | AX8: Tidak | AY8: Tidak | AZ8: Ya | BA8: Tidak | BC8: B | BD8: Bahasa Inggris | BE8: Dapat Membantu dalam hal pengembangan ataupun pembuatan sistem aplikasi khususnya di bidang kearsiapan dan perpustakaan
B9: 2016 | C9: Diploma Empat/ Sarjana Terapan | D9: D4 Produksi Film dan Televisi | E9: 12510160042 | F9: Akbar Jefri Duardi | G9: Siti Fatimah, S.Pd | H9: 081330948050 | I9: - | J9: SMKN 1 Trowulan | K9: Jl. Mawar 1 Kec. Trowulan | L9: (0321) 4890348 | M9: Pendidikan | N9: 2 | O9: 4 | P9: SB | Q9: SB | R9: SB | S9: SB | T9: SB | U9: B | V9: B | W9: B | X9: B | Y9: SB | Z9: SB | AA9: SB | AB9: SB | AC9: SB | AD9: B | AE9: SB | AF9: B | AG9: B | AH9: SB | AI9: B | AJ9: SB | AK9: SB | AL9: B | AM9: B | AN9: B | AO9: SB | AP9: SB | AQ9: B | AR9: SB | AS9: Perlu | AT9: Keterampilan Mengajar / Menyampaikan Materi | AU9: Ya | AV9: Masih kekurangan Tenaga TI | AW9: Ya | AX9: Ya | AY9: Ya | AZ9: Ya | BA9: Tidak | BB9: Penyerapan Tenaga Kerja Kompetensi TI | BC9: SB | BD9: Bahasa Inggris, Pengembangan diri | BE9: Lulusan Yg berkompetensi dan siap diberikan tugas apapun karena kompetensi TI yang memiliki ruang cukup luas
B10: 2016 | C10: Sarjana | D10: S1 Desain Komunikasi Visual | E10: 12420100008 | F10: Moch. Romawan Pradhikta Satriyadi | G10: Moch Romawan Pradhikta S | H10: 081334454059 | I10: m.romawan.p.s@gmail.com | J10: PT. Rejoso Manis Indo | K10: Betek, Rejoso, Binanungn, Blitar | L10: - | M10: Industri Pabrik Gul | N10: 1 | O10: 12 | P10: B | Q10: B | R10: B | S10: B | T10: B | U10: B | V10: B | W10: B | X10: B | Y10: B | Z10: B | AA10: B | AB10: B | AC10: B | AD10: B | AE10: B | AF10: B | AG10: B | AH10: B | AI10: B | AJ10: B | AK10: B | AL10: B | AM10: B | AN10: B | AO10: B | AP10: B | AQ10: B | AR10: B | AS10: Tidak perlu | AT10: - | AU10: Ya | AV10: Dunia Digital (internet) | AW10: Tidak | AX10: Tidak | AY10: - | AZ10: Ya | BA10: Tidak | BB10: Saat ini belum | BC10: B | BD10: Bahasa Inggris | BE10: Bagian IT Desain maupun yang berurusan dengan internet
B11: 2016 | C11: Sarjana | D11: S1 Desain Komunikasi Visual | E11: 12420100016 | F11: Uzda Nabila Shabiriani | G11: Putri Lestari | H11: 081932541992 | I11: putrikyl@gmail.com | J11: Cv. Laju Laksana Lestari | K11: Jl. Belawan No 16A, Jakarta 10150 | L11: 021-3513650 | M11: Perdagangan / Bisnis | N11: 1 | O11: 6 | P11: B | Q11: B | R11: B | S11: B | T11: B | U11: B | V11: B | W11: B | X11: B | Y11: B | Z11: B | AA11: B | AB11: B | AC11: B | AD11: B | AE11: B | AF11: B | AG11: B | AH11: B | AI11: B | AJ11: B | AK11: B | AL11: B | AM11: B | AN11: B | AO11: K | AP11: B | AQ11: B | AR11: B | AS11: Tidak perlu | AU11: Ya | AW11: Tidak | AX11: Tidak | AY11: Tidak | AZ11: Ya | BA11: Tidak | BB11: - | BC11: B | BD11: Komunikasi, Pengembangan Diri | BE11: - Lebih banyak expose e dunia kerja - Lebih profesional
B12: 2016 | C12: Sarjana | D12: S1 Desain Komunikasi Visual | E12: 12420100049 | F12: Juke Andiya Fidiyanti | G12: andiya F | H12: 82257650673 | I12: jukealan712@yahoo.co.id | J12: Wiraswasta | K12: - | L12: - | M12: - | N12: - | O12: 12 | P12: K | Q12: B | R12: K | S12: SB | T12: B | U12: B | V12: B | W12: SK | X12: SK | Y12: K | Z12: SK | AA12: K | AB12: B | AC12: K | AD12: B | AE12: SK | AF12: B | AG12: SK | AH12: B | AI12: K | AJ12: B | AK12: B | AL12: B | AM12: K | AN12: K | AO12: K | AP12: B | AQ12: K | AR12: K | AS12: Tidak Perlu | AT12: - | AU12: Tidak | AV12: - | AW12: Tidak | AX12: Tidak | AY12: Tidak | AZ12: Tidak | BA12: Tidak | BB12: - | BC12: B | BD12: Keahlian Berdasarkan Bidang Ilmu | BE12: -
B13: 2016 | C13: Sarjana | D13: S1 Desain Komunikasi Visual | E13: 12420100062 | F13: Muhammad Nur Fithriyadi | G13: Muklib | H13: 08113003383 | I13: bca.travel@gmail.com | J13: PT. Barokah Cahaya Arafah | K13: Jl. Romokalisari Surabaya | L13: 031 - 3971728 | M13: Jasa Umroh | N13: 7 | O13: 4 | P13: B | Q13: B | R13: B | S13: B | T13: B | U13: B | V13: B | W13: K | X13: K | Y13: B | Z13: K | AA13: B | AB13: B | AC13: B | AD13: B | AE13: K | AF13: K | AG13: K | AH13: K | AI13: K | AJ13: K | AK13: K | AL13: B | AM13: K | AN13: K | AO13: K | AP13: K | AQ13: K | AR13: K | AS13: Perlu | AT13: - | AU13: Ya | AV13: - | AW13: Ya | AX13: Tidak | AY13: Ya | AZ13: Ya | BA13: Ya | BB13: It dan Marketing | BC13: B | BD13: Komunikasi, Pengembangan Diri | BE13: Mampu dengan cara sendiri menyiapkan kebutuan pimpinan / perusahaan
B14: 2016 | C14: Sarjana | D14: S1 Desain Komunikasi Visual | E14: 12420100068 | F14: Mira Shabrina | G14: Shierly Iwanto | H14: 082132500880 | I14: Shierlyi@getcommerce.co.id | J14: PT. Global Indo Inovatif | K14: Ngagel Jaya Selatan 15g | L14: 031- 99444949 | M14: Jasa, Pengoperasian AKun Online | N14: 1 | O14: 6 | P14: B | Q14: SB | R14: B | S14: SB | T14: B | U14: B | V14: B | W14: B | X14: SB | Y14: SB | Z14: SB | AA14: SB | AB14: B | AC14: B | AD14: B | AE14: K | AF14: B | AG14: B | AH14: B | AI14: K | AJ14: B | AK14: K | AL14: B | AM14: SB | AN14: K | AO14: B | AP14: B | AQ14: K | AR14: B | AS14: Tidak Perlu | AT14: - | AU14: Ya | AV14: - | AW14: Ya | AX14: Tidak | AY14: Ya | AZ14: Ya | BA14: Tidak | BB14: - | BC14: B | BD14: Pengembangan Diri | BE14: Memahami setiap bidang / imlu dari semua mawa kuliah yang dijalani
B15: 2016 | C15: Sarjana | D15: S1 Desain Komunikasi Visual | E15: 12420100075 | F15: Ibadurrokhman | G15: Ibad | H15: 08213943001 | I15: irn031@yahoo.com | J15: rudabi | K15: Dukuh setro 10/54 | L15: 082139430011 | M15: Jasa, 3D Visualisasi / Desain | N15: 1 | O15: 12 | P15: B | Q15: B | R15: B | S15: B | T15: B | U15: SB | V15: SB | W15: K | X15: K | Y15: SB | Z15: SB | AA15: B | AB15: B | AC15: B | AD15: B | AE15: B | AF15: B | AG15: SB | AH15: SB | AI15: SB | AJ15: B | AK15: B | AL15: SB | AM15: B | AN15: B | AO15: K | AP15: SB | AQ15: B | AR15: B | AS15: Tidak perlu | AU15: Tidak | AW15: Tidak | AX15: Tidak | AY15: Ya | AZ15: Ya | BA15: Tidak | BB15: - | BC15: B | BD15: - | BE15: -
B16: 2016 | C16: Sarjana | D16: S1 Sistem Informasi | E16: 8410100375 | F16: Purwanto | G16: Erny Indah Trimastuti Mpd | H16: 08121679621 | I16: - | J16: SMK Antartika 2 Sidoarjo | K16: Jl. Siwalan Panji, Buduran Sidoarjo | L16: (031) 8065117 | M16: Pendidikan | N16: 1 | O16: 12 | P16: B | Q16: SB | R16: B | S16: SB | T16: SB | U16: SB | V16: SB | W16: K | X16: K | Y16: SB | Z16: SB | AA16: B | AB16: B | AC16: B | AD16: B | AE16: B | AF16: B | AG16: B | AH16: B | AI16: B | AJ16: B | AK16: B | AL16: B | AM16: B | AN16: B | AO16: B | AP16: SB | AQ16: SB | AR16: B | AS16: Perlu | AT16: Tambah ilmu kuliah yang berhubungan dengan ilmu kependidikan | AU16: Ya | AV16: - | AW16: Ya | AX16: Ya | AY16: Ya | AZ16: Ya | BA16: Tidak | BB16: Bidang Teknologi Informasi | BC16: B | BD16: Bahasa Inggris, Pengembangan Diri
B17: 2016 | C17: Sarjana | D17: S1 Sistem Informasi | E17: 8410100454 | F17: Riyadi Atmajaya | G17: Dana Badrie | H17: 081938588920 | I17: dana@boga-jatim.id | J17: PT. Boga makmur abadi | K17: Jl. Raya Satelit Indah AN-10 | L17: - | M17: Jasa Restaurant | N17: 1 | O17: 24 | P17: B | Q17: SB | R17: B | S17: B | T17: B | U17: SB | V17: B | W17: B | X17: B | Y17: B | Z17: B | AA17: SB | AB17: B | AC17: B | AD17: SB | AE17: B | AF17: B | AG17: B | AH17: SB | AI17: SB | AJ17: B | AK17: B | AL17: B | AM17: B | AN17: SB | AO17: B | AP17: B | AQ17: B | AR17: B | AS17: - | AT17: - | AU17: - | AV17: - | AW17: Tidak | AX17: Tidak | AY17: Ya | AZ17: Tidak | BA17: Tidak | BB17: - | BC17: B | BD17: Penggunaan TI, Komunikasi, Kerjasama Tim, Pengembangan Diri | BE17: -
B18: 2016 | C18: Sarjana | D18: S1 Sistem Informasi | E18: 8410100471 | F18: Yuli Setiyo Suryo Andari | G18: Yuvita | H18: 08113527122 | I18: Yuvita@stikom.edu | J18: Institut Bisnis dan Informatika Stikom Surabaya | K18: Jl. Raya Kedung Baruk no 98 Sby | L18: 031-8721731 | M18: Pendidikan | N18: 1 | O18: 204 | P18: B | Q18: B | R18: B | S18: SB | T18: SB | U18: B | V18: B | W18: K | X18: K | Y18: SB | Z18: SB | AA18: SB | AB18: SB | AC18: B | AD18: B | AE18: B | AF18: B | AG18: B | AH18: B | AI18: B | AJ18: B | AK18: B | AL18: B | AM18: B | AN18: B | AO18: B | AP18: B | AQ18: B | AR18: B | AS18: Perlu | AT18: - | AU18: Ya | AV18: - | AW18: Tidak | AX18: Ya | AY18: Ya | AZ18: Ya | BA18: Ya | BB18: Keuangan | BC18: B | BD18: Bahasa Inggris, Akutansi & Perpajakan & Perbankan | BE18: Yang mengerti tentang akuntansi, perpajakan dan perbankan
B19: 2016 | C19: Sarjana | D19: S1 Sistem Informasi | E19: 9410100018 | F19: Oktavianus Eko Pambudi Adinugroho | G19: Fanino Raynardo, ST,. MMT. | H19: 085102530303 | I19: Fanino@rkzsby.com | J19: RS Katholik St. Vincentius | K19: Jl. Diponegoro 51 | L19: (031_ 5677562 | M19: Kesehatan (Rumah Sakit) | N19: 2 | O19: 24 | P19: SB | Q19: SB | R19: SB | S19: SB | T19: SB | U19: SB | V19: SB | W19: B | X19: B | Y19: SB | Z19: SB | AA19: SB | AB19: SB | AC19: SB | AD19: SB | AE19: SB | AF19: SB | AG19: SB | AH19: SB | AI19: SB | AJ19: SB | AK19: SB | AL19: SB | AM19: SB | AN19: SB | AO19: B | AP19: B | AQ19: B | AR19: SB | AS19: Perlu | AT19: Mobile App developer | AU19: Ya | AV19: Mobile App & Networking | AW19: Ya | AX19: Ya | AY19: Ya | AZ19: Ya | BA19: - | BB19: - | BC19: B | BD19: Komunikasi, Kerjasama Tim, Pengembangan Diri, Skill Networking dan Mobile App | BE19: -
B20: 2016 | C20: Sarjana | D20: S1 Sistem Informasi | E20: 9410100060 | F20: Arif Rahman | G20: Arif Rahman (wirausaha) | H20: 087851233686 | I20: Arifinspire7@gmail.com | J20: CV. Cipta Karya Pratama | K20: Bendul Merisi Utara No 22 Surabaya | L20: 031-8433430 | M20: Percetakan | N20: 1 | O20: 24 | P20: B | Q20: B | R20: SB | S20: B | T20: B | U20: K | V20: B | W20: B | X20: B | Y20: B | Z20: B | AA20: B | AB20: B | AC20: B | AD20: B | AE20: B | AF20: K | AG20: B | AH20: B | AI20: SB | AJ20: B | AK20: K | AL20: B | AM20: B | AN20: B | AO20: B | AP20: B | AQ20: K | AR20: B | AS20: Perlu | AT20: Sofsskill | AU20: Ya | AV20: TI Dibutuhkan untuk beberapa aspek, selain untuk proses produksi, juga diperlukan dalam customer relationship, dsb | AW20: Ya | AX20: Ya | AY20: Ya | AZ20: Ya | BA20: Ya | BB20: - | BC20: B | BD20: Keahlian berdasarkan bidang ilmu, Bahasa inggris | BE20: Yang dibutuhkan adalah yang mampu berpikir kedepan untuk menciptakan inovasi dan kreasi baru untuk menunjang kegiatan bisnis, selain itu, yang paling utama adalah softskill, Sehingga mampu bertahan dan berkembang di dunia kerja / bisnis
B21: 2016 | C21: Sarjana | D21: S1 Sistem Informasi | E21: 9410100154 | F21: Helko Prasetiyo | G21: Dina Wahyuningsari | H21: 082141560349 | I21: Dinajt90@gmail.com | J21: PT. Bank Mandiri (persero) Tbk | K21: Jl. Ahmad yani no 16-18 Mall Royal Plaza | L21: - | M21: Perbankan | N21: 5 | O21: 12 | P21: SB | Q21: SB | R21: SB | S21: SB | T21: SB | U21: B | V21: SB | W21: B | X21: B | Y21: SB | Z21: SB | AA21: SB | AB21: B | AC21: SB | AD21: SB | AE21: SB | AF21: SB | AG21: B | AH21: SB | AI21: SB | AJ21: SB | AK21: SB | AL21: SB | AM21: SB | AN21: SB | AO21: SB | AP21: SB | AQ21: SB | AR21: SB | AS21: Perlu | AU21: Ya | AW21: Ya | AX21: Tidak | AY21: Tidak | AZ21: Ya | BA21: Tidak | BC21: SB | BD21: Bahasa Inggris, Komunikasi, Pengembangan Diri | BE21: Yang bisa bekerja teamwork yang B, Memiliki etos kerja yang B, memiliki etika kerja dalam organisasi yang B, kopmunikatif dan aktif, mencapai target yang telah di tetapkan
B22: 2016 | C22: Sarjana | D22: S1 Sistem Informasi | E22: 9410100170 | F22: M. Septian Maulana | G22: Meinarni | H22: - | I22: meinarni@telkomsel.co.id | J22: Telkomsel | K22: Jl. A Yani Km 57 | L22: 0511-4229907 | M22: Lain - Lain, Telekomunikasi | N22: 1 | O22: 12 | P22: B | Q22: B | R22: B | S22: B | T22: B | U22: SB | V22: B | W22: K | X22: K | Y22: B | Z22: B | AA22: B | AB22: B | AC22: B | AD22: B | AE22: B | AF22: B | AG22: B | AH22: B | AI22: SB | AJ22: SB | AK22: B | AL22: SB | AM22: B | AN22: B | AO22: B | AP22: B | AQ22: B | AR22: B | AS22: Tidak Perlu | AT22: - | AU22: Ya | AV22: Sudah | AW22: Ya | AX22: Ya | AY22: Ya | AZ22: Ya | BA22: Tidak | BB22: Share Knowledge | BC22: SB | BD22: Bahasa Inggris | BE22: -
B23: 2016 | C23: Sarjana | D23: S1 Sistem Informasi | E23: 9410100195 | F23: Yudiyanto Salay | G23: Hernawati | H23: 0813328411841 | I23: - | J23: UD Erlangga | K23: Mojoarum u1/15 | L23: 031-5942769 | M23: Perdagangan / Bisnis | N23: 1 | O23: 60 | P23: SB | Q23: SB | R23: B | S23: SB | T23: SB | U23: B | V23: SB | W23: SB | X23: SB | Y23: SB | Z23: SB | AA23: B | AB23: B | AC23: SB | AD23: B | AE23: B | AF23: B | AG23: B | AH23: B | AI23: SB | AJ23: SB | AK23: B | AL23: B | AM23: SB | AN23: SB | AO23: SB | AP23: B | AQ23: B | AR23: B | AS23: Tidak Perlu | AT23: - | AU23: Ya | AV23: Karena Mengikuti Perkembangan Zaman | AW23: Tidak | AX23: Tidak | AY23: Tidak | AZ23: Tidak | BA23: Tidak | BC23: SB | BD23: Keahlian Berdasarkan Bidang Ilmu | BE23: -
B24: 2016 | C24: Sarjana | D24: S1 Sistem Informasi | E24: 9410100235 | F24: Hilmy Nur Ramdhani | G24: Rukmantono Dimas Nughroho | H24: 081330300720 | I24: dimas@agatos.com | J24: PT. Agatos Multi Solusi | K24: Ruko Rungkut Megah Raya A-32 Sby | L24: 031-8714143 | M24: Jasa, Information & Control Solution Provider | N24: 9 | O24: 24 | P24: SB | Q24: SB | R24: SB | S24: SB | T24: SB | U24: B | V24: SB | W24: SB | X24: SB | Y24: SB | Z24: SB | AA24: SB | AB24: SB | AC24: SB | AD24: SB | AE24: SB | AF24: SB | AG24: SB | AH24: SB | AI24: SB | AJ24: SB | AK24: SB | AL24: SB | AM24: SB | AN24: SB | AO24: SB | AP24: SB | AQ24: SB | AR24: SB | AS24: Perlu | AT24: Bahasa Mandarin | AU24: Ya | AV24: Mobile App Developer | AW24: Tidak | AX24: Tidak | AY24: Ya | AZ24: Tidak | BA24: Tidak | BB24: - | BC24: SB | BD24: Mobile app & Bahasa Mandarin | BE24: IT for Industrial environment, Factoring floor, a little bit knowledge on PLC, mobile app for industry
B25: 2016 | C25: Sarjana | D25: S1 Sistem Informasi | E25: 9410100252 | F25: Kaisha Satrio Noor Hutomo | G25: Ana Listiowati T | H25: 081331660329 | I25: ana@match-Advertising.com | J25: PT. Multi Artistikacithra | K25: Jl. Lesti No 42 Surabaya | L25: 031-5678346 | M25: Jasa, Periklan | N25: 3 | O25: 3 | P25: B | Q25: B | R25: B | S25: B | T25: B | U25: B | V25: B | W25: K | X25: K | Y25: B | Z25: B | AA25: B | AB25: B | AC25: B | AD25: B | AE25: B | AF25: B | AG25: B | AH25: B | AI25: B | AJ25: B | AK25: B | AL25: B | AM25: B | AN25: B | AO25: B | AP25: B | AQ25: B | AR25: B | AS25: Perlu | AT25: - | AU25: Ya | AW25: Tidak | AX25: Tidak | AY25: Ya | AZ25: Ya | BA25: Tidak | BC25: B | BD25: Bahasa Inggris, Pengembangan Diri | BE25: Yang bisa mengikuti Perkembangan teknologi yang terbaru
B26: 2016 | C26: Sarjana | D26: S1 Sistem Informasi | E26: 10410100049 | F26: Fikry Nurris Rizky | G26: Amrih Widayati | H26: 081336124235 | I26: amrihwidyawati@btn.co.id | J26: PT. Bank Tabungan Negara persero Tbk | K26: Jl. A.Yani no 5 Jember | L26: 0331 - 484611 | M26: Perbankan | N26: 1 | O26: 24 | P26: SB | Q26: SB | R26: SB | S26: SB | T26: SB | U26: B | V26: SB | W26: B | X26: B | Y26: SB | Z26: SB | AA26: SB | AB26: SB | AC26: SB | AD26: SB | AE26: B | AF26: B | AG26: B | AH26: SB | AI26: SB | AJ26: SB | AK26: B | AL26: SB | AM26: SB | AN26: SB | AO26: SB | AP26: SB | AQ26: SB | AR26: SB | AS26: Perlu | AT26: Yang sesuai dengan perkembangan Baru T.I di bidang Perbankan | AU26: Ya | AV26: Yang sesuai dengna perkembangan T.I | AW26: T | AX26: T | AY26: Y | AZ26: Y | BA26: T | BB26: - | BC26: SB | BD26: Bahasa Inggris, Pengembangan Diri | BE26: -
B27: 2016 | C27: Sarjana | D27: S1 Sistem Informasi | E27: 10410100066 | F27: Ni Nyoman Swastika Juniarti | G27: Erwin | H27: 081515380388 | I27: Erwin@dwp.co.id | J27: PT. Dutakom Wibawa Putra | K27: Jl. Basuki Rahmat 106-128 Graha Bumi Surabaya | L27: 031-5480500 | M27: Jasa, Internet Service Provider | N27: 1 | O27: 24 | P27: B | Q27: B | R27: B | S27: SB | T27: SB | U27: B | V27: B | W27: B | X27: B | Y27: B | Z27: B | AA27: SB | AB27: SB | AC27: SB | AD27: B | AE27: B | AF27: B | AG27: B | AH27: B | AI27: B | AJ27: B | AK27: B | AL27: B | AM27: B | AN27: B | AO27: B | AP27: B | AQ27: B | AR27: B | AS27: Perlu | AT27: - | AU27: Ya | AV27: - | AW27: Ya | AX27: Tidak | AY27: Ya | AZ27: Ya | BA27: Ya | BB27: - | BC27: B | BD27: Bahasa Inggris, Komunikasi | BE27: Kemampuan Berpikir Kritis, Lebih Mengenal Problema di Lapangan, Fast Learner, Kemampuan Bahasa Inggris Yang B
B28: 2016 | C28: Sarjana | D28: S1 Sistem Informasi | E28: 10410100088 | F28: Novita Kurniasari | G28: Trami Endang Asmoro Putri | H28: 08113430585 | I28: Buminatasurabaya@gmail.com | J28: PT. Bumi Nata Wisata Tours and Travel | K28: Jl. Gayung Sari I no 42, Surabaya | L28: 08113430585 | M28: Jasa, Tours and Travel Umroh & Haji | N28: 1 | O28: 24 | P28: B | Q28: B | R28: B | S28: B | T28: B | U28: B | V28: B | W28: B | X28: B | Y28: B | Z28: B | AA28: B | AB28: B | AC28: B | AD28: B | AE28: B | AF28: B | AG28: B | AH28: B | AI28: B | AJ28: B | AK28: B | AL28: B | AM28: B | AN28: B | AO28: B | AP28: B | AQ28: B | AR28: B | AS28: Perlu | AT28: Materi Kerja lapangan / Praktek langsung dan Survey untuk kemajuan Ti yang semakin maju dan bnyak novasi baru | AU28: Ya | AV28: TI sangat penting guna kemajuan dan kelancaran info serta berita terbaru agar institusi tetap upgrade dan tidak ketinggalan informasi dan ketinggalan kemajuan TI | AW28: Ya | AX28: Ya | AY28: Ya | AZ28: Ya | BA28: Ya | BB28: Pemasaran program / Paket Tour Wisata dan Umroh + Haji | BC28: B | BD28: Pengembangan diri | BE28: Cepat, Tanggap, Selalu up to date berbagai informasi di berbagai media ( Elektornik, sosmed, periklanan), Suple, teknik negosiasi, serta teknik pemasaran yang sesuai dengan erkembangan jaman dan teknologi
B29: 2016 | C29: Sarjana | D29: S1 Sistem Informasi | E29: 10410100104 | F29: Dewi Ayu Khusnul Khotimah | G29: Dewi Ayu | H29: 0844392226 | I29: dewiayukk@gmail.com | J29: CV. Kardi Putra Motor | K29: Jl. Raya Cangkir No5, Driyorejo Gresik | L29: 085259333704 | M29: Jasa Jual beli dan Persewaan Mobil | N29: 1 | O29: 12 | P29: SB | Q29: SB | R29: SB | S29: SB | T29: SB | U29: B | V29: SB | W29: SB | X29: SB | Y29: SB | Z29: SB | AA29: B | AB29: SB | AC29: SB | AD29: SB | AE29: B | AF29: SB | AG29: SB | AH29: SB | AI29: SB | AJ29: B | AK29: B | AL29: SB | AM29: SB | AN29: SB | AO29: B | AP29: B | AQ29: SB | AR29: SB | AS29: Perlu | AT29: Memperdalam ilmu management Keuangan | AU29: Ya | AV29: TI berbasis management | AW29: Tidak | AX29: Tidak | AY29: Ya | AZ29: Ya | BA29: Tidak | BB29: Akutansi dan Management | BC29: SB | BD29: Lainnya, AKutansi | BE29: Yang Mengerti lebih dalam tentang ilmu akutansi
B30: 2016 | C30: Sarjana | D30: S1 Sistem Informasi | E30: 10410100106 | F30: Ignatius Rahardhi | G30: Fanino Naynarno St, MMT | H30: 085102530303 | I30: Fanino@rkzsby.com | J30: RS Katolik St. Vincentius Sa Paulo | K30: Diponegoro 51 Sby | L30: 031 - 5677562 | M30: Jasa Kesehatan | N30: 2 | O30: 24 | P30: SB | Q30: SB | R30: SB | S30: SB | T30: SB | U30: SB | V30: SB | W30: B | X30: B | Y30: SB | Z30: SB | AA30: SB | AB30: SB | AC30: SB | AD30: SB | AE30: SB | AF30: SB | AG30: SB | AH30: SB | AI30: SB | AJ30: SB | AK30: SB | AL30: SB | AM30: SB | AN30: SB | AO30: B | AP30: B | AQ30: B | AR30: SB | AS30: Perlu | AT30: Manajemen Server & Jaringan | AU30: Ya | AV30: Pengelolaan Server dan jaringan | AW30: Ya | AX30: Ya | AY30: Ya | AZ30: Ya | BA30: - | BB30: - | BC30: B | BE30: Komunikasi, Kerjasama TIm, Pengembangan Diri, Mobile APP
B31: 2016 | C31: Sarjana | D31: S1 Sistem Informasi | E31: 10410100107 | F31: Malkus Willybrodus Se | G31: Syamsul | H31: - | I31: - | J31: Taspen Persero | K31: Jalan Letjend Suprapto No.45, Jakarta Pusat | L31: - | M31: Jasa Asuransi | N31: 1 | O31: 12 | P31: SB | Q31: SB | R31: SB | S31: SB | T31: SB | U31: B | V31: SB | W31: B | X31: B | Y31: SB | Z31: SB | AA31: SB | AB31: SB | AC31: SB | AD31: SB | AE31: B | AF31: SB | AG31: SB | AH31: SB | AI31: SB | AJ31: B | AK31: B | AL31: SB | AM31: SB | AN31: SB | AO31: B | AP31: B | AQ31: B | AR31: SB | AS31: Perlu | AT31: - | AU31: Ya | AV31: - | AW31: Ya | AX31: Ya | AY31: Tidak | AZ31: Tidak | BA31: Tidak | BB31: - | BC31: B | BD31: - | BE31: -
B32: 2016 | C32: Sarjana | D32: S1 Sistem Informasi | E32: 10410100120 | F32: Asdi Atmin Fildananto | G32: Gartinia Murcholis, M.Psi, Psi | H32: 081231127099 | I32: gartina.nurcholis@hangtuah.ac.id | J32: Unversitas Hang Tuah Surabaya | K32: Jl. Arief Rahman Hakim 150 Sby | L32: - | M32: 2 | N32: 2 | O32: 60 | P32: B | Q32: B | R32: B | S32: B | T32: B | U32: SB | V32: B | W32: K | X32: B | Y32: SB | Z32: SB | AA32: B | AB32: B | AC32: B | AD32: B | AE32: B | AF32: B | AG32: B | AH32: SB | AI32: B | AJ32: B | AK32: B | AL32: B | AM32: B | AN32: B | AO32: B | AP32: B | AQ32: K | AR32: B | AS32: Tidak Perlu | AT32: - | AU32: Ya | AV32: - | AW32: Ya | AX32: Ya | AY32: Ya | AZ32: Ya | BA32: Tidak | BB32: - | BC32: Baol | BD32: Bahasa Inggris | BE32: - Mampu Menguasai TI untuk mendukung proese pembelajaran - Mampu untuk memberikan inovasi pengembangan sistem informasi PT - Mampu memberikan pelayanan dengan cepat dan tepat - Mampu menyelesaikan masalah (Problem Solving) di lingkungan dan B
B33: 2016 | C33: Sarjana | D33: S1 Sistem Informasi | E33: 10410100188 | F33: Feriyan | G33: Denny A Idiarto | H33: 08111732665 | I33: idiarto@telkom.co.id | J33: PT. Telkom | K33: Jl. Kebalen Timur 2 Sby | L33: - | M33: Telekomunikasi | N33: 1 | O33: 12 | P33: B | Q33: SB | R33: B | S33: B | T33: B | U33: B | V33: B | W33: K | X33: K | Y33: SB | Z33: SB | AA33: B | AB33: B | AC33: B | AD33: B | AE33: B | AF33: B | AG33: B | AH33: SB | AI33: SB | AJ33: B | AK33: B | AL33: B | AM33: B | AN33: B | AO33: B | AP33: B | AQ33: B | AR33: B | AS33: Perlu | AT33: Broadcasting | AU33: Ya | AV33: Mengerti tentang Broadcasting | AW33: Ya | AX33: Ya | AY33: Ya | AZ33: Ya | BA33: Ya | BB33: Berkaitan dengan jasa telekomunikasi dan Broadcasting | BC33: B | BD33: Bahasa Inggris | BE33: Yang Mengerti tentang Broadacsting dan telekomunikasi in the future
B34: 2016 | C34: Sarjana | D34: S1 Sistem Informasi | E34: 10410100209 | F34: M. Ramzi | G34: Ilmanza Restuadi K | H34: 08113620797 | I34: Ilmanza.kurniawan@semenindonesia.com | J34: PT. Semen Indonesia | K34: Jl. Veteran Gresik | L34: 031 3981732 | M34: Indsutri Semen | N34: 10 | O34: 12 | P34: B | Q34: B | R34: B | S34: B | T34: B | U34: B | V34: B | W34: K | X34: B | Y34: B | Z34: B | AA34: B | AB34: B | AC34: B | AD34: B | AE34: B | AF34: B | AG34: B | AH34: B | AI34: SB | AJ34: B | AK34: B | AL34: B | AM34: B | AN34: B | AO34: B | AP34: B | AQ34: K | AR34: SB | AS34: Perlu | AT34: IOT dan Mobile APPS | AU34: Ya | AV34: IOT dan Mobile Apps | AW34: Ya | AX34: Ya | AY34: Ya | AZ34: Ya | BA34: Tidak | BC34: B | BD34: Bahasa Inggris, Mobile Apps dan IOT
B35: 2016 | C35: Sarjana | D35: S1 Sistem Informasi | E35: 10410100240 | F35: Prabu Prasetya Meifa | G35: Alfi Erlangga | H35: 08124111850 | I35: alfi@alive-resort.com | J35: alive Resort | K35: Menara BCA lt.50 Jakarta Pusat | L35: 02123584487 | M35: Property | N35: 1 | O35: 12 | P35: B | Q35: B | R35: B | S35: B | T35: B | U35: B | V35: B | W35: K | X35: B | Y35: SB | Z35: SB | AA35: B | AB35: B | AC35: B | AD35: SB | AE35: B | AF35: B | AG35: B | AH35: B | AI35: K | AJ35: B | AK35: SB | AL35: SB | AM35: SB | AN35: B | AO35: SB | AP35: B | AQ35: B | AR35: B | AS35: Perlu | AT35: Digital Marketing | AU35: Ya | AV35: Update Perkembangan IT | AW35: Tidak | AX35: Tidak | AY35: Ya | AZ35: Tidak | BA35: Ya | BB35: - | BC35: B | BD35: Bahasa Inggris | BE35: Update IT Terkini
B36: 2016 | C36: Sarjana | D36: S1 Sistem Informasi | E36: 11410100020 | F36: I Putu Narario Sastra | G36: Jingo Saputra | H36: 085733344881 | I36: jingosaputra@japfa.com | J36: PT. Comas Adisatwa | K36: Hr. Mangundiprojo KM 3,5 Sidoarjo | L36: 0312988329 | M36: Industri Poultry Processing | N36: 2 | O36: 60 | P36: B | Q36: B | R36: B | S36: SB | T36: B | U36: B | V36: B | W36: K | X36: B | Y36: B | Z36: B | AA36: B | AB36: B | AC36: B | AD36: B | AE36: B | AF36: B | AG36: K | AH36: B | AI36: B | AJ36: B | AK36: B | AL36: B | AM36: B | AN36: B | AO36: K | AP36: K | AQ36: K | AR36: B | AS36: Perlu | AT36: Matakuliah Pengasahan Logika | AU36: - | AV36: - | AW36: Tidak | AX36: Tidak | AY36: Ya | AZ36: Tidak | BA36: Tidak | BB36: - | BC36: B | BD36: - | BE36: Yang mampu dan Mau secara aktif mencari solusi / Inovasi terhadap suatu permasalhan
B37: 2016 | C37: Sarjana | D37: S1 Sistem Informasi | E37: 11410100031 | F37: Priyanggoro Dwi Hananto | G37: Jingo Saputra | H37: 085733344881 | I37: jingosaputra@japfa.com | J37: PT. Comas Adisatwa | K37: Hr. Mangundiprojo KM 3,5 Sidoarjo | L37: 0312988329 | M37: Industri Poultry Processing | N37: 2 | O37: 60 | P37: B | Q37: B | R37: B | S37: SB | T37: B | U37: B | V37: B | W37: K | X37: B | Y37: B | Z37: B | AA37: B | AB37: B | AC37: B | AD37: B | AE37: B | AF37: B | AG37: K | AH37: B | AI37: B | AJ37: B | AK37: B | AL37: B | AM37: B | AN37: B | AO37: K | AP37: K | AQ37: K | AR37: B | AS37: Perlu | AT37: Matakuliah Pengasahan Logika | AU37: - | AV37: - | AW37: Tidak | AX37: Tidak | AY37: Ya | AZ37: Tidak | BA37: Tidak | BB37: - | BC37: B | BD37: - | BE37: Yang mampu dan Mau secara aktif mencari solusi / Inovasi terhadap suatu permasalhan
B38: 2016 | C38: Sarjana | D38: S1 Sistem Informasi | E38: 11410100042 | F38: Aldy Hafil Ananda | G38: The Fang | H38: 081216570707 | I38: f-fang7i@yahoo.com | J38: PT. BPR INTAN KITA | K38: Jl. Panglima Sudirman 76B Gresik | L38: 031-3981597 , 031-3988333 | M38: Jasa Keuangan (PERBANKAN) | N38: 1 | O38: 6 | P38: SB | Q38: SB | R38: SB | S38: SB | T38: SB | U38: SB | V38: SB | W38: B | X38: B | Y38: SB | Z38: SB | AA38: SB | AB38: SB | AC38: SB | AD38: SB | AE38: SB | AF38: B | AG38: B | AH38: B | AI38: B | AJ38: SB | AK38: SB | AL38: SB | AM38: SB | AN38: SB | AO38: SB | AP38: SB | AQ38: SB | AR38: SB | AS38: Perlu, | AT38: Program di Aplikasi android - HP | AU38: Ya | AV38: Yang Sesuai kebutuhan dan perkembangan TI 5-10 th mendatang | AW38: Tidak | AX38: Ya | AY38: Ya | AZ38: Ya | BA38: Ya | BB38: Promosi Produk, Info Loker | BC38: SB | BD38: - | BE38: Saat ini memenuhi kebutuhan yang perusahaan butuhkan
B39: 2016 | C39: Sarjana | D39: S1 Sistem Informasi | E39: 11410100073 | F39: Febi Kadarianto | G39: Puguh Triyono | H39: 081252831567 | I39: puguh@sucofindo.co.id | J39: PT. Sucofindo (Persero) | K39: Jl. Kalibutuh no 215 Surabaya | L39: 031 - 5469123 | M39: Jasa, Inspeksi, Pengujian Sertifikasi | N39: 5 | O39: 24 | P39: SB | Q39: SB | R39: SB | S39: SB | T39: SB | U39: B | V39: SB | W39: B | X39: B | Y39: SB | Z39: SB | AA39: SB | AB39: SB | AC39: SB | AD39: SB | AE39: SB | AF39: SB | AG39: SB | AH39: SB | AI39: SB | AJ39: SB | AK39: SB | AL39: SB | AM39: SB | AN39: SB | AO39: SB | AP39: SB | AQ39: SB | AR39: SB | AS39: Perlu | AT39: Sistem Auditor | AU39: Ya | AV39: - | AW39: Ya | AX39: Tidak | AY39: Tidak | AZ39: Ya | BA39: Tidak | BB39: - | BC39: SB | BD39: Bahasa Inggris
B40: 2016 | C40: Sarjana | D40: S1 Sistem Informasi | E40: 11410100075 | F40: Zulfikar Rahman | G40: Ade Gunardi didi | H40: 08122111989 | I40: adegede@gmail.com | J40: PT. Atmajaya Makmur Gemilang | K40: Jl. Raya Jemursari No 15 Srabaya | L40: 031-8485665 | M40: Indsutri Pupuk | N40: 1 | O40: 24 | P40: B | Q40: SB | R40: B | S40: B | T40: B | U40: B | V40: B | W40: B | X40: B | Y40: SB | Z40: B | AA40: SB | AB40: B | AC40: B | AD40: B | AE40: B | AF40: SB | AG40: B | AH40: B | AI40: B | AJ40: B | AK40: B | AL40: B | AM40: SB | AN40: B | AO40: B | AP40: B | AQ40: B | AR40: B | AS40: Tidak Perlu | AT40: - | AU40: Ya | AW40: Ya | AX40: Tidak | AY40: Ya | AZ40: Ya | BA40: Tidak | BB40: - | BC40: B | BD40: Bahasa Inggris | BE40: Memiliki skill teknis yang B dnegna tambahan mempunyai wawasan yang cukup tentang soft skill (team management, interpersonal, relationship, communication, dll)
...

Sheet Th. Lulus 2017
G1: A | P1: B | U1: C | W1: D | Y1: E | AA1: F | AD1: G | AF1: H | AJ1: I.a | AO1: I.b | AS1: J | AW1: K1 | BC1: L1
B2: th lulus | C2: Program Pendidikan | D2: Prodi | E2: Nim | F2: Nama Alumni | G2: A1 | H2: A2 | I2: A3 | J2: A4 | K2: A5 | L2: A6 | M2: A7 | N2: A8 | O2: A9 Bulan | P2: B1 | Q2: B2 | R2: B3 | S2: B4 | T2: B5 | U2: C1 | V2: C2 | W2: D1 | X2: D2 | Y2: E1 | Z2: E2 | AA2: F1 | AB2: F2 | AC2: F3 | AD2: G1 | AE2: G2 | AF2: H1 | AG2: H2 | AH2: H3 | AI2: H4 | AJ2: I. a1 | AK2: I. a2 | AL2: I. a3 | AM2: I. a4 | AN2: I. a5 | AO2: I. b1 | AP2: I. b2 | AQ2: I. b3 | AR2: I. b4 | AS2: J1 | AT2: J2 | AU2: J3 | AV2: J4 | AW2: K1 | AX2: K2 | AY2: K3 | AZ2: K4 | BA2: K5 | BB2: K6 | BC2: L1 | BD2: L2 | BE2: L3
B3: 2017 | C3: Diploma Tiga | D3: D3 Administrasi Perkantoran | E3: 12390150003 | F3: Ricky Ahmad Rinaldi | G3: Rinaldi | H3: 08523474699 | I3: - | J3: Casual WO | K3: - | L3: - | M3: Event Organizer | N3: 1 | O3: 24 | P3: B | Q3: B | R3: B | S3: B | T3: B | U3: B | V3: B | W3: B | X3: B | Y3: B | Z3: B | AA3: B | AB3: B | AC3: B | AD3: B | AE3: B | AF3: B | AG3: B | AH3: B | AI3: B | AJ3: SB | AK3: SB | AL3: SB | AM3: SB | AN3: SB | AO3: SB | AP3: SB | AQ3: SB | AR3: B | AS3: Perlu | AU3: Ya | AV3: IT | AW3: Tidak | AX3: Ya | AY3: Ya | AZ3: Ya | BA3: Tidak | BB3: - | BC3: SB | BD3: - | BE3: -
B4: 2017 | C4: Diploma Tiga | D4: D3 Administrasi Perkantoran | E4: 13390150003 | F4: Anugerah Yustisia Utama | G4: Nandhi Kusuma,. ST., MT | H4: 0859311774662 | I4: nandhikusuma@gmail.com | J4: kementrian Sosial | K4: Mojopanggung no 15, Banyuwangi | L4: - | M4: Sosial | N4: 1 | O4: 8 | P4: B | Q4: B | R4: B | S4: B | T4: B | U4: B | V4: B | W4: B | X4: B | Y4: B | Z4: B | AA4: B | AB4: B | AC4: B | AD4: B | AE4: B | AF4: B | AG4: B | AH4: B | AI4: B | AJ4: B | AK4: B | AL4: B | AM4: B | AN4: B | AO4: B | AP4: B | AQ4: B | AR4: B | AS4: Perlu | AU4: Ya | AV4: IT | AW4: Tidak | AX4: Ya | AY4: Ya | AZ4: Ya | BA4: Tidak | BB4: - | BC4: SB | BD4: integritas Lulusan, Keahlian berdasar bidang ilmu, Bahasa inggris, Komunikasi | BE4: Yang memiliki keahlian dalam hal teknologi informasi
B5: 2017 | C5: Diploma Tiga | D5: D3 Administrasi Perkantoran | E5: 14390150003 | F5: Indah Gita Cahyani | G5: Jefri S | H5: - | I5: info@wellracom.co.id | J5: Wellracom Group | K5: Jl. Bratang Binangun 83-85, Surabaya | L5: 031-501888 | M5: Perdagangan, bisnis | N5: 1 | O5: 12 | P5: SB | Q5: SB | R5: SB | S5: SB | T5: SB | U5: SB | V5: SB | W5: B | X5: B | Y5: B | Z5: SB | AA5: B | AB5: SB | AC5: SB | AD5: B | AE5: B | AF5: SB | AG5: SB | AH5: SB | AI5: SB | AJ5: SB | AK5: SB | AL5: SB | AM5: SB | AN5: SB | AO5: SB | AP5: SB | AQ5: SB | AR5: SB | AS5: Perlu | AT5: - | AU5: Ya | AV5: - | AW5: Ya | AX5: Ya | AY5: Ya | AZ5: Ya | BA5: Ya | BB5: - | BC5: B | BD5: - | BE5: -
B6: 2017 | C6: Diploma Tiga | D6: D3 Administrasi Perkantoran | E6: 14390150008 | F6: Galih Permata Putra | G6: Indra Gunawan | H6: 085234770077 | I6: Gunawan@dinamika.ac.id | J6: Universitas Dinamika | K6: Jl. Raya Kedung baruk no 98 | L6: 031 8721731 | M6: Pendidikan | N6: 1 | O6: 36 | P6: B | Q6: B | R6: B | S6: B | T6: B | U6: B | V6: B | W6: K | X6: K | Y6: B | Z6: B | AA6: B | AB6: B | AC6: B | AD6: B | AE6: B | AF6: B | AG6: B | AH6: B | AI6: K | AJ6: K | AK6: B | AL6: B | AM6: B | AN6: B | AO6: K | AP6: B | AQ6: K | AR6: B | AS6: Tidak Perlu | AU6: Ya | AV6: - | AW6: Tidak | AX6: Ya | AY6: Ya | AZ6: Ya | BA6: Tidak | BB6: Museum dan IT | BC6: B | BD6: Bahasa Inggris, Pengembangan diri, semangat | BE6: Semangat kerja, Disiplin waktu, menguasai dibidangnya
B7: 2017 | C7: Diploma Tiga | D7: D3 Administrasi Perkantoran | E7: 14390150009 | F7: Darin Ramadhani Nisrina | G7: Mochamad Faisal | H7: 081330306718 | I7: mfaisal_tgp@yahoo.com | J7: PT Ptangguh Gada Pratama | K7: Griya Bhayangkara F2/5, Sidoarjo | L7: 031-7879881 | M7: jasa Outsourching | N7: 1 | O7: 24 | P7: SB | Q7: SB | R7: SB | S7: SB | T7: SB | U7: SB | V7: SB | W7: B | X7: B | Y7: SB | Z7: SB | AA7: B | AB7: B | AC7: B | AD7: SB | AE7: B | AF7: SB | AG7: SB | AH7: SB | AI7: SB | AJ7: SB | AK7: SB | AL7: SB | AM7: SB | AN7: SB | AO7: SB | AP7: SB | AQ7: SB | AR7: SB | AS7: Perlu | AT7: Tender di LPSE | AU7: Ya | AV7: - | AW7: Tidak | AX7: Tidak | AY7: Tidak | AZ7: Tidak | BA7: Tidak | BB7: - | BC7: SB | BD7: - | BE7: -
B8: 2017 | C8: Diploma Tiga | D8: D3 Administrasi Perkantoran | E8: 14390150017 | F8: Icha Reznanda Ramadhania | G8: Brahma Satrya | H8: 08113237799 | I8: Satryabrahmagmail.com | J8: PTPN XII | K8: Jl. Rajawali 44 Surabaya | L8: 0313524893 | M8: Perdagangan, bisnis | N8: 1 | O8: 24 | P8: SB | Q8: SB | R8: SB | S8: SB | T8: SB | U8: SB | V8: SB | W8: B | X8: B | Y8: B | Z8: SB | AA8: B | AB8: SB | AC8: SB | AD8: B | AE8: B | AF8: SB | AG8: SB | AH8: SB | AI8: SB | AJ8: SB | AK8: SB | AL8: SB | AM8: SB | AN8: SB | AO8: SB | AP8: SB | AQ8: SB | AR8: SB | AS8: Perlu | AT8: Cyber Security | AU8: Ya | AV8: - | AW8: Ya | AX8: Ya | AY8: Ya | AZ8: Ya | BA8: Ya | BB8: Dalam bidang Ti, Dapat memberikan materi pada karyawan | BC8: B | BD8: - | BE8: -
B9: 2017 | C9: Diploma Tiga | D9: D3 Sistem Informasi | E9: 14390100023 | F9: Kadek Ayu Putri Meydiana | G9: Tyas | H9: 085655386290 | I9: Recruitment@merakjaya.co.id | J9: Merak jaya Beton | K9: Jl. Barata Jaya No.46 | L9: 0315042034 | M9: Perdagangan, Industri semen | N9: 1 | O9: 12 | P9: B | Q9: SB | R9: B | S9: B | T9: SB | U9: B | V9: SB | W9: B | X9: B | Y9: SB | Z9: B | AA9: B | AB9: B | AC9: B | AD9: SB | AE9: B | AF9: B | AG9: B | AH9: B | AI9: B | AJ9: B | AK9: B | AL9: SB | AM9: B | AN9: B | AO9: B | AP9: B | AQ9: B | AR9: B | AS9: Perlu | AT9: Android Mobile Dev | AU9: Ya | AV9: Teknologi Artificial Intelligence | AW9: Ya | AX9: Ya | AY9: Ya | AZ9: Ya | BA9: Tidak | BB9: - | BC9: SB | BD9: Pengembangan Diri | BE9: -
B10: 2017 | C10: Diploma Tiga | D10: D3 Sistem Informasi | E10: 12390100019 | F10: Mochamad Catur Nurhidayad | G10: Yefta | H10: 81574266656 | I10: Yefta.tsw@gmail.com | J10: SMPK Ronggolawe Tuban | K10: Jl. Kh. Ahmad Dahlan no 4, Tuban | L10: (0356) 321672 | M10: Pendidikan | N10: 1 | O10: 6 | P10: SB | Q10: B | R10: SB | S10: B | T10: B | U10: B | V10: SB | W10: B | X10: B | Y10: SB | Z10: SB | AA10: B | AB10: B | AC10: B | AD10: SB | AE10: SB | AF10: B | AG10: SB | AH10: B | AI10: SB | AJ10: B | AK10: B | AL10: SB | AM10: B | AN10: B | AO10: SB | AP10: SB | AQ10: SB | AR10: SB | AS10: Perlu | AU10: Ya | AW10: Tidak | AX10: Ya | AY10: Ya | AZ10: Ya | BA10: Tidak | BB10: Workshop Software skills untuk Guru | BC10: B | BD10: Pengembangan Diri | BE10: Lulusan yang mampu menciptakan inovasi baru dibidang teknologi informasi terutama yang berkaitan dengan dunia pendidikan
B11: 2017 | C11: Diploma Tiga | D11: D3 Sistem Informasi | E11: 14390100021 | F11: Septi Aisyah Duanasari | G11: Erwin Qurnia | H11: 08113343355 | I11: Captain.surockboyo@gmail.com | J11: PT. Infomedia Nusantara | K11: Jl. A. Yani no 88, Grahapena | L11: 031-8288604 | M11: Jasa, Contact Center | N11: 5 | O11: 24 | P11: B | Q11: SB | R11: B | S11: B | T11: SB | U11: B | V11: SB | W11: B | X11: B | Y11: SB | Z11: B | AA11: B | AB11: B | AC11: B | AD11: SB | AE11: B | AF11: B | AG11: B | AH11: B | AI11: B | AJ11: B | AK11: B | AL11: SB | AM11: B | AN11: B | AO11: B | AP11: B | AQ11: B | AR11: B | AS11: Perlu | AT11: Android Mobile Dev | AU11: Ya | AV11: Teknologi Artificial Intelligence | AW11: Ya | AX11: Ya | AY11: Ya | AZ11: Ya | BA11: Tidak | BB11: - | BC11: B | BD11: Komunikasi | BE11: Skill Komunikasi, Desain Grafis, Lebih Kreatif
B12: 2017 | C12: Diploma Tiga | D12: D3 Sistem Informasi | E12: 14390100025 | F12: Atika Rizky Damayanti | G12: Agus S Hidayat | H12: 08119105038 | I12: Agus.Hidayat@slackware_id.org | J12: PT. BTPN | K12: Jl. Indrapura 1 EFE, Surabaya | L12: 031 - 3533054 | M12: Perbankan | N12: 1 | O12: 6 | P12: B | Q12: B | R12: B | S12: B | T12: B | U12: B | V12: B | W12: B | X12: B | Y12: B | Z12: B | AA12: B | AB12: B | AC12: B | AD12: B | AE12: B | AF12: B | AG12: B | AH12: B | AI12: B | AJ12: B | AK12: B | AL12: B | AM12: B | AN12: B | AO12: B | AP12: B | AQ12: B | AR12: B | AS12: Perlu | AT12: - | AU12: Ya | AV12: - | AW12: Tidak | AX12: Tidak | AY12: Ya | AZ12: Tidak | BA12: Tidak | BB12: - | BC12: B | BD12: Bahasa Inggris | BE12: -
B13: 2017 | C13: Diploma Empat/ Sarjana Terapan | D13: D4 Produksi Film dan Televisi | E13: 13510160008 | F13: Angelina Febrianti | G13: Mansa Chandra | H13: 0811316018 | I13: mansa@hakiki.com | J13: PT. Hakiki Donarta | K13: Jl. Sikatan 39 Surabaya | L13: 031-3551221 | M13: Industri dan Perdagangan dan Bisnis | N13: 1 | O13: 12 | P13: SB | Q13: SB | R13: B | S13: SB | T13: SB | U13: K | V13: SB | W13: SB | X13: SB | Y13: SB | Z13: SB | AA13: SB | AB13: B | AC13: SB | AD13: SB | AE13: SB | AF13: SB | AG13: SB | AH13: SB | AI13: SB | AJ13: SB | AK13: SB | AL13: SB | AM13: SB | AN13: SB | AO13: B | AP13: SB | AQ13: SB | AR13: B | AS13: Perlu | AT13: Ya | AU13: Tidak | AV13: Ya | AW13: Tidak | AX13: Ya | AY13: Ya | AZ13: Tidak | BA13: Ya | BB13: Marketing, Sales, Management, IT, Design | BC13: SB | BD13: - | BE13: Komunikatif, Kreatif, Up To date
B14: 2017 | C14: Diploma Empat/ Sarjana Terapan | D14: D4 Produksi Film dan Televisi | E14: 13510160045 | F14: Fajar Alingga Mukti | G14: Alingga | H14: 0817379420 | I14: alinnga.fajar@gmail.com | J14: Alingga Adv | K14: Jl. Raya Kali Rungkut No.72, Kali Rungkut | L14: - | M14: Jasa Advertising | N14: 1 | O14: 24 | P14: SB | Q14: SB | R14: B | S14: SB | T14: SB | U14: K | V14: SB | W14: SB | X14: SB | Y14: SB | Z14: B | AA14: B | AB14: B | AC14: B | AD14: SB | AE14: B | AF14: B | AG14: B | AH14: B | AI14: B | AJ14: B | AK14: B | AL14: SB | AM14: B | AN14: B | AO14: B | AP14: B | AQ14: B | AR14: B | AS14: Perlu | AT14: Ya | AU14: Tidak | AV14: Ya | AW14: Tidak | AX14: Ya | AY14: Ya | AZ14: Tidak | BA14: Ya | BC14: SB | BD14: -
B15: 2017 | C15: Sarjana | D15: S1 Desain Komunikasi Visual | E15: 13420100017 | F15: Kinanthi Arum Mustika Wardhani | G15: Melinda Fungkyana | H15: 082133480344 | I15: meme_melin@rocketmail.com | J15: PT. Persada Bhinneka Nusantara | K15: Jl. Raya Kupang Indah no 17 surabaya | L15: 03199147807 | M15: Property | N15: 2 | O15: 36 | P15: B | Q15: SB | R15: B | S15: B | T15: B | U15: B | V15: B | W15: K | X15: B | Y15: B | Z15: B | AA15: SB | AB15: B | AC15: B | AD15: B | AE15: K | AF15: B | AG15: B | AH15: B | AI15: B | AJ15: B | AK15: B | AL15: B | AM15: B | AN15: SB | AO15: B | AP15: B | AQ15: B | AR15: B | AS15: Tidak Perlu | AU15: Ya | AV15: Periklanan , Sosial media, dll | AW15: Tidak | AX15: Tidak | AY15: Ya | AZ15: Tidak | BA15: Tidak | BB15: - | BC15: B | BD15: Bahasa Inggris | BE15: Dapat lebih menguasai penggunaan web untuk bahan promosi
B16: 2017 | C16: Sarjana | D16: S1 Sistem Informasi | E16: 11410110017 | F16: Resi Mairapon Saputra | G16: Romeo | H16: 0817390037 | I16: romeo@ray.co.id | J16: PT. Renjana Abi Yasa | K16: jl. Jemursari1 no 1A Surabaya | L16: 0318417117 | M16: Pendidikan, Software House | N16: 36 | O16: 48 | P16: B | Q16: B | R16: K | S16: B | T16: B | U16: B | V16: K | W16: K | X16: K | Y16: B | Z16: K | AA16: B | AB16: B | AC16: B | AD16: B | AE16: K | AF16: B | AG16: K | AH16: B | AI16: K | AJ16: B | AK16: B | AL16: B | AM16: B | AN16: B | AO16: K | AP16: K | AQ16: K | AR16: B | AS16: Perlu | AT16: Bahasa Pemrograman yang terkini | AU16: ya | AV16: Programmer (API, Mobile, Web) | AW16: Ya | AX16: Ya | AY16: Ya | AZ16: Ya | BA16: Ya | BB16: Software Development | BC16: B | BD16: Keahlian berdasar bidang ilmu, bahasa inggris, penggunaan Teknologi informasi, Pengambangan diri | BE16: Kreatif,loyal,Dapat berfikir Kritis,Mau dan mampu belajar hal baru dengna cepat,mampu bekerja dalam tim,mampu bekerja dalam tekanan
B17: 2017 | C17: Sarjana | D17: S1 Sistem Informasi | E17: 11410110034 | F17: Dony Purwanto | G17: Agustina Dwi Indrayanti | H17: 089615125477 | I17: agustina@dinamika.ac.id | J17: Universitas Dinamika | K17: Jl. Kedung baruk no 98 | L17: 0318721731 | M17: Pendidikan | N17: 3 | O17: 48 | P17: SB | Q17: SB | R17: B | S17: SB | T17: SB | U17: SB | V17: SB | W17: B | X17: B | Y17: SB | Z17: SB | AA17: SB | AB17: SB | AC17: SB | AD17: SB | AE17: B | AF17: B | AG17: K | AH17: B | AI17: K | AJ17: B | AK17: B | AL17: B | AM17: B | AN17: B | AO17: K | AP17: K | AQ17: K | AR17: B | AS17: Tidak perlu | AT17: - | AU17: Ya | AV17: - | AW17: Ya | AX17: Ya | AY17: Ya | AZ17: Ya | BA17: Ya | BB17: - | BC17: SB | BD17: - | BE17: -
B18: 2017 | C18: Sarjana | D18: S1 Sistem Informasi | E18: 12410110012 | F18: Fendi Puji Atmiko | G18: Renny Dwi Ocktavia | H18: 082333679690 | I18: hrd@genesysindonesia.com | J18: PT. Genesys Integrated Indonesia | K18: Jl. Margorejo Indah II / A-317, Sby 60238 | L18: 031-8498188 | M18: Jasa, Konsultan IT | N18: 3 | O18: 32 | P18: B | Q18: SB | R18: SB | S18: B | T18: B | U18: SB | V18: SB | W18: B | X18: B | Y18: SB | Z18: SB | AA18: B | AB18: B | AC18: B | AD18: SB | AE18: SB | AF18: B | AG18: B | AH18: SB | AI18: B | AJ18: B | AK18: B | AL18: SB | AM18: SB | AN18: SB | AO18: SB | AP18: SB | AQ18: SB | AR18: SB | AS18: Perlu | AT18: Diajarkan teknologi baru | AU18: Ya | AV18: Programmer | AW18: Tidak | AX18: Tidak | AY18: Ya | AZ18: Ya | BA18: Tidak | BB18: - | BC18: SB | BD18: Tidak kurang, namun hanya perlu ditingkatkan | BE18: Update teknologi baru, kreative, dan inovative
B19: 2017 | C19: Sarjana | D19: S1 Sistem Informasi | E19: 12410110032 | F19: Muhammad Sigit Pambudi | G19: Ratna Sari | H19: 081232560876 | I19: hrdpapayadas@gmail.com | J19: PT. Masuya Sejati | K19: Jl. Raya Darmo Permai 3-5 | L19: 0317310990 | M19: Perdagangan, bisnis | N19: 2 | O19: 36 | P19: SB | Q19: SB | R19: SB | S19: SB | T19: SB | U19: SB | V19: SB | W19: B | X19: B | Y19: SB | Z19: SB | AA19: SB | AB19: SB | AC19: SB | AD19: SB | AE19: SB | AF19: SB | AG19: SB | AH19: SB | AI19: SB | AJ19: SB | AK19: SB | AL19: SB | AM19: SB | AN19: SB | AO19: SB | AP19: SB | AQ19: SB | AR19: SB | AS19: Tidak perlu | AU19: Ya | AV19: IT | AW19: Tidak | AX19: Tidak | AY19: Ya | AZ19: Tidak | BA19: Tidak | BB19: - | BC19: SB | BD19: Pengembangan Diri | BE19: -
B20: 2017 | C20: Sarjana | D20: S1 Sistem Informasi | E20: 12410110006 | F20: Inka Patresia Walangitan | G20: M.M Sekar Dewanti | H20: 087852880076 | I20: Sekar@dinamika.ac.id | J20: Universitas Dinamika | K20: Jl. Raya Kedung baruk no 98 | L20: 031-8721731 | M20: Pendidikan | N20: 1 | O20: 24 | P20: SB | Q20: SB | R20: SB | S20: SB | T20: SB | U20: SB | V20: SB | W20: B | X20: B | Y20: SB | Z20: SB | AA20: SB | AB20: SB | AC20: SB | AD20: SB | AE20: SB | AF20: SB | AG20: SB | AH20: SB | AI20: SB | AJ20: SB | AK20: SB | AL20: SB | AM20: SB | AN20: SB | AO20: SB | AP20: SB | AQ20: B | AR20: SB | AS20: Perlu | AT20: Bahasa Asing, Selain Bahasa Inggris | AU20: Ya | AV20: Pengolahan Database | AW20: Tidak | AX20: Ya | AY20: Ya | AZ20: Tidak | BA20: Tidak | BB20: - | BC20: SB | BD20: Inovasi dan Bahasa Asing non Inggris | BE20: Kreatif,loyal,Dapat berfikir Kritis,Mau dan mampu belajar hal baru dengna cepat,mampu bekerja dalam tim,mampu bekerja dalam tekanan
B21: 2017 | C21: Sarjana | D21: S1 Sistem Informasi | E21: 8410100302 | F21: Muhammad Ridwan Bahar | G21: Aries Kurniawan ST | H21: 08122170848 | I21: Aries.kurniawan@lapan.co.id | J21: BPAA SUMEDANG (LAPAN) | K21: Jl. Raya Bandung Sumedang - Km 31 | L21: 0227911262 | M21: Lembagan Pemerintah non kementrian | N21: 1 | O21: 35 | P21: B | Q21: B | R21: B | S21: B | T21: B | U21: SB | V21: B | W21: B | X21: K | Y21: B | Z21: B | AA21: SB | AB21: SB | AC21: SB | AD21: SB | AE21: B | AF21: SB | AG21: B | AH21: B | AI21: B | AJ21: B | AK21: B | AL21: B | AM21: B | AN21: B | AO21: B | AP21: B | AQ21: B | AR21: B | AS21: Perlu | AT21: Pemrobraman Mobile | AU21: Ya | AV21: * | AW21: Tidak | AX21: Tidak | AY21: Ya | AZ21: Ya | BA21: Tidak | BB21: * | BC21: B | BD21: Keahlian Berdasarkan Bidang Ilmu, bahasa Inggris | BE21: Kreatif,loyal,Dapat berfikir Kritis,Mau dan mampu belajar hal baru dengna cepat,mampu bekerja dalam tim,mampu bekerja dalam tekanan
B22: 2017 | C22: Sarjana | D22: S1 Sistem Informasi | E22: 9410100036 | F22: Dwi Kusuma Wardana | G22: Romeo | H22: 0817390037 | I22: romeo@ray.co.id | J22: PT. Renjana Abi Yasa | K22: jl. Jemursari1 no 1A Surabaya | L22: 0318417117 | M22: Pendidikan, Software House | N22: 36 | O22: 48 | P22: B | Q22: B | R22: K | S22: B | T22: B | U22: B | V22: K | W22: K | X22: K | Y22: B | Z22: K | AA22: B | AB22: B | AC22: B | AD22: B | AE22: K | AF22: B | AG22: K | AH22: B | AI22: K | AJ22: B | AK22: B | AL22: B | AM22: B | AN22: B | AO22: K | AP22: K | AQ22: K | AR22: B | AS22: Perlu | AT22: Bahasa Pemrograman yang terkini | AU22: ya | AV22: Programmer (API, Mobile, Web) | AW22: Ya | AX22: Ya | AY22: Ya | AZ22: Ya | BA22: Ya | BB22: Software Development | BC22: B | BD22: Keahlian berdasar bidang ilmu, bahasa inggris, penggunaan Teknologi informasi, Pengambangan diri | BE22: Kreatif,loyal,Dapat berfikir Kritis,Mau dan mampu belajar hal baru dengna cepat,mampu bekerja dalam tim,mampu bekerja dalam tekanan
B23: 2017 | C23: Sarjana | D23: S1 Sistem Informasi | E23: 9410100038 | F23: Andrew Bagus Wicaksono Verdyanwar | G23: Romeo | H23: 0817390037 | I23: romeo@ray.co.id | J23: PT. Renjana Abi Yasa | K23: jl. Jemursari1 no 1A Surabaya | L23: 0318417117 | M23: Pendidikan, Software House | N23: 36 | O23: 48 | P23: B | Q23: B | R23: K | S23: B | T23: B | U23: B | V23: K | W23: K | X23: K | Y23: B | Z23: K | AA23: B | AB23: B | AC23: B | AD23: B | AE23: K | AF23: B | AG23: K | AH23: B | AI23: K | AJ23: B | AK23: B | AL23: B | AM23: B | AN23: B | AO23: K | AP23: K | AQ23: K | AR23: B | AS23: Perlu | AT23: Bahasa Pemrograman yang terkini | AU23: ya | AV23: Programmer (API, Mobile, Web) | AW23: Ya | AX23: Ya | AY23: Ya | AZ23: Ya | BA23: Ya | BB23: Software Development | BC23: B | BD23: Keahlian berdasar bidang ilmu, bahasa inggris, penggunaan Teknologi informasi, Pengambangan diri | BE23: Kreatif,loyal,Dapat berfikir Kritis,Mau dan mampu belajar hal baru dengna cepat,mampu bekerja dalam tim,mampu bekerja dalam tekanan
B24: 2017 | C24: Sarjana | D24: S1 Sistem Informasi | E24: 10410100201 | F24: Achmad Sony Syaiful Aziz | G24: Kardinah | H24: 082142142313 | I24: Kardinah@gmail.com / Kardinah@telkom.co.id | J24: PT. Telekomunikasi Indonesia (Surabaya) | K24: Jl. Mergoyoso 1-3 Surabaya | L24: 031-5450700 | M24: Telekomunikasi | N24: 2 | O24: 24 | P24: SB | Q24: SB | R24: B | S24: SB | T24: SB | U24: SB | V24: B | W24: B | X24: B | Y24: SB | Z24: SB | AA24: SB | AB24: SB | AC24: SB | AD24: SB | AE24: B | AF24: SB | AG24: B | AH24: SB | AI24: SB | AJ24: B | AK24: SB | AL24: SB | AM24: B | AN24: SB | AO24: B | AP24: SB | AQ24: SB | AR24: B | AS24: Tidak | AT24: - | AU24: Ya | AV24: Bidang IT Perusahaan | AW24: Tidak | AX24: Tidak | AY24: Ya | AZ24: Ya | BA24: Ya | BB24: - | BC24: SB | BD24: Intergritas Lulusan, Keahlian berdasar Bidang Ilmu, Penggunaan TI, Komunikasi, Kerjasama Tim | BE24: -
B25: 2017 | C25: Sarjana | D25: S1 Sistem Informasi | E25: 10410100241 | F25: Lukman Arie Setio Budi | G25: Sigit Pangestu | H25: 85645255840 | I25: sigitpangestu88@gmail.com | J25: RSUD RA Basoeni | K25: Jl. Raya Gedeg no 17 , Mojokerto | L25: 0321-364752 | M25: Jasa Pelayanan Kesehatan | N25: 1 | O25: 8 | P25: B | Q25: B | R25: B | S25: B | T25: SB | U25: B | V25: B | W25: K | X25: B | Y25: B | Z25: B | AA25: SB | AB25: SB | AC25: SB | AD25: SB | AE25: B | AF25: B | AG25: B | AH25: B | AI25: B | AJ25: SB | AK25: B | AL25: B | AM25: B | AN25: SB | AO25: B | AP25: B | AQ25: B | AR25: B | AS25: Perlu | AT25: Untuk Mengatasi Persaingan | AU25: Ta | AV25: Semua yang membahas TI | AW25: Tidak | AX25: Tidak | AY25: Tidak | AZ25: Tidak | BA25: Tidak | BB25: - | BC25: B | BD25: Bahasa Inggris | BE25: Mudah Beradaptasi dengan lingkungan
B26: 2017 | C26: Sarjana | D26: S1 Sistem Informasi | E26: 10410100245 | F26: Isnainul Amanda Perwirasari | G26: Erwin Sutomo | H26: 08977431599 | I26: Sutomo@dinamika.ac.id | J26: Universitas Dinamika | K26: Jl. Raya Kedung baruk no 98 | L26: 031-8721731 | M26: Pendidikan | N26: 7 | O26: 48 | P26: SB | Q26: SB | R26: B | S26: SB | T26: SB | U26: SB | V26: SB | W26: B | X26: B | Y26: SB | Z26: SB | AA26: SB | AB26: SB | AC26: SB | AD26: SB | AE26: B | AF26: SB | AG26: B | AH26: SB | AI26: SB | AJ26: SB | AK26: SB | AL26: SB | AM26: SB | AN26: SB | AO26: B | AP26: SB | AQ26: B | AR26: SB | AS26: Perlu | AT26: Mobile Apps Programming | AU26: Ya | AV26: Mobile Apps Programming | AW26: Ya | AX26: Ya | AY26: Ya | AZ26: Ya | BA26: Ya | BB26: Kerja Praktik dan Tugas Akhir | BC26: SB | BD26: Bahasa Asing Selain inggris | BE26: Mau eksplorasi sesuatu yang baru, memiliki endurance / daya tahan kerja yang B
B27: 2017 | C27: Sarjana | D27: S1 Sistem Informasi | E27: 11410100130 | F27: Brian Nusual Karyana Murti | G27: Nusual K | H27: 08123299090 | I27: - | J27: Venturo | K27: Jl. Madiun no 3, Gresik | L27: 081231257473 | M27: Perdagangan, bisnis | N27: 1 | O27: 24 | P27: B | Q27: B | R27: B | S27: SB | T27: SB | U27: B | V27: B | W27: B | X27: B | Y27: SB | Z27: SB | AA27: SB | AB27: B | AC27: B | AD27: SB | AE27: B | AF27: K | AG27: K | AH27: B | AI27: B | AJ27: SB | AK27: B | AL27: B | AM27: B | AN27: B | AO27: B | AP27: B | AQ27: K | AR27: K | AS27: Perlu | AT27: Optimasi pengelolaan Gudang | AU27: Ya | AV27: Sistem informasi Gudang | AW27: Tidak | AX27: Tidak | AY27: Tidak | AZ27: Ya | BA27: Tidak | BB27: - | BC27: B | BD27: Integritas Lulusan | BE27: Untuk saat ini kami membutuhkan lulusan TI untuk perawatan Jaringan
B28: 2017 | C28: Sarjana | D28: S1 Sistem Informasi | E28: 11410100203 | F28: Robiyanto | G28: Ilmanza Restuadi | H28: - | I28: - | J28: Sinergi Informatika Semen Indonesia | K28: Jl. Veteran Gresik Jawa Timur 61122 | L28: 031-3972091 | M28: Industri | N28: 6 | O28: 24 | P28: SB | Q28: SB | R28: B | S28: SB | T28: SB | U28: SB | V28: SB | W28: B | X28: B | Y28: SB | Z28: SB | AA28: SB | AB28: SB | AC28: SB | AD28: SB | AE28: B | AF28: SB | AG28: B | AH28: SB | AI28: SB | AJ28: SB | AK28: SB | AL28: SB | AM28: SB | AN28: SB | AO28: B | AP28: SB | AQ28: B | AR28: SB | AS28: Perlu | AT28: Mobile Apps Programming | AU28: Ya | AV28: Mobile Apps Programming | AW28: Ya | AX28: Ya | AY28: Ya | AZ28: Ya | BA28: Ya | BB28: - | BC28: SB | BD28: ERP | BE28: -
B29: 2017 | C29: Sarjana | D29: S1 Sistem Informasi | E29: 11410100272 | F29: Ivan Christiono Suharnoko | G29: Agustina Dwi Indrayanti | H29: 089615125477 | I29: agustina@dinamika.ac.id | J29: Universitas Dinamika | K29: Jl. Kedung baruk no 98 | L29: 0318721731 | M29: Pendidikan | N29: 3 | O29: 48 | P29: SB | Q29: SB | R29: B | S29: SB | T29: SB | U29: SB | V29: SB | W29: B | X29: B | Y29: SB | Z29: SB | AA29: SB | AB29: SB | AC29: SB | AD29: SB | AE29: B | AF29: B | AG29: K | AH29: B | AI29: K | AJ29: B | AK29: B | AL29: B | AM29: B | AN29: B | AO29: K | AP29: K | AQ29: K | AR29: B | AS29: Tidak perlu | AT29: - | AU29: Ya | AV29: - | AW29: Ya | AX29: Ya | AY29: Ya | AZ29: Ya | BA29: Ya | BB29: - | BC29: SB | BD29: - | BE29: -
B30: 2017 | C30: Sarjana | D30: S1 Sistem Informasi | E30: 12410100076 | F30: Agus Ariyanto | G30: Romeo | H30: 0817390037 | I30: romeo@ray.co.id | J30: PT. Renjana Abi Yasa | K30: jl. Jemursari1 no 1A Surabaya | L30: 0318417117 | M30: Pendidikan, Software House | N30: 36 | O30: 48 | P30: B | Q30: B | R30: K | S30: B | T30: B | U30: B | V30: K | W30: K | X30: K | Y30: B | Z30: K | AA30: B | AB30: B | AC30: B | AD30: B | AE30: K | AF30: B | AG30: K | AH30: B | AI30: K | AJ30: B | AK30: B | AL30: B | AM30: B | AN30: B | AO30: K | AP30: K | AQ30: K | AR30: B | AS30: Perlu | AT30: Bahasa Pemrograman yang terkini | AU30: ya | AV30: Programmer (API, Mobile, Web) | AW30: Ya | AX30: Ya | AY30: Ya | AZ30: Ya | BA30: Ya | BB30: Software Development | BC30: B | BD30: Keahlian berdasar bidang ilmu, bahasa inggris, penggunaan Teknologi informasi, Pengambangan diri | BE30: Kreatif,loyal,Dapat berfikir Kritis,Mau dan mampu belajar hal baru dengna cepat,mampu bekerja dalam tim,mampu bekerja dalam tekanan
B31: 2017 | C31: Sarjana | D31: S1 Sistem Informasi | E31: 13410100032 | F31: Tantri Mindrawan | G31: Yongki Agustinus | H31: 087862035757 | I31: Yongki@fantasktic.com | J31: PT. Fantasktic Teknologi Indonesia | K31: Jl. Sunses Road Tengah 80, Pertokoan Sunset 88, Bali | L31: - | M31: jasa Website Development | N31: 1 | O31: 12 | P31: SB | Q31: SB | R31: SB | S31: SB | T31: SB | U31: SB | V31: SB | W31: SB | X31: SB | Y31: SB | Z31: SB | AA31: B | AB31: SB | AC31: SB | AD31: SB | AE31: SB | AF31: SB | AG31: SB | AH31: SB | AI31: SB | AJ31: SB | AK31: SB | AL31: SB | AM31: SB | AN31: SB | AO31: SB | AP31: SB | AQ31: SB | AR31: SB | AS31: Perlu | AT31: Materi untuk Teknologi dan Pemrograman Terbaru | AU31: Tidak | AV31: - | AW31: Ya | AX31: Ya | AY31: Ya | AZ31: Ya | BA31: Ya | BB31: Workshop / Event Teknologi | BC31: SB | BD31: Tidak Ada | BE31: Profesional dan dapat beradaptasi dengan perkembangan Teknologi
B32: 2017 | C32: Sarjana | D32: S1 Sistem Informasi | E32: 11410100052 | F32: Anugrah Reksa Pradana | G32: F. Wenny C | H32: 082140056157 | I32: WennyChorniawati@yahoo.co.id | J32: Univ. Widya Mandala Sby | K32: Jl. Raya kaliasin selatan no 1 | L32: 031-99005299 | M32: Pendidikan | N32: 1 | O32: 24 | P32: B | Q32: SB | R32: B | S32: SB | T32: B | U32: SB | V32: B | W32: B | X32: B | Y32: SB | Z32: SB | AA32: SB | AB32: B | AC32: B | AD32: B | AE32: B | AF32: B | AG32: B | AH32: B | AI32: B | AJ32: B | AK32: B | AL32: B | AM32: B | AN32: B | AO32: B | AP32: B | AQ32: B | AR32: B | AS32: Perlu | AT32: Update dengan program terbaru | AU32: Ya | AV32: - | AW32: Tidak | AX32: Tidak | AY32: Ya | AZ32: Tidak | BA32: Ya | BB32: - | BC32: B | BD32: - | BE32: -
B33: 2017 | C33: Sarjana | D33: S1 Sistem Informasi | E33: 11410100085 | F33: Gazza Muhammad Oetama | G33: Totok Sugioto | H33: 081252398111 | I33: Maryadi23@gmail.com | J33: Bank Jatim | K33: Jl. Semolowaru 45 | L33: - | M33: Perbankan | N33: 1 | O33: 12 | P33: SB | Q33: B | R33: B | S33: SB | T33: SB | U33: B | V33: SB | W33: SB | X33: SB | Y33: SB | Z33: B | AA33: B | AB33: B | AC33: B | AD33: SB | AE33: B | AF33: SB | AG33: B | AH33: B | AI33: SB | AJ33: SB | AK33: B | AL33: SB | AM33: B | AN33: SB | AO33: B | AP33: B | AQ33: B | AR33: SB | AS33: Perlu | AT33: Teknologi Perbankan | AU33: Ya | AV33: Ya | AW33: Ya | AX33: Ya | AY33: Ya | AZ33: Ya | BA33: Ya | BB33: - | BC33: B | BD33: Integritas Lulusa, Bahasa Inggris | BE33: -
